Workbook

Sheet dataset
A1: FID | B1: id | C1: agency_code | D1: region_code | E1: national_fire_id | F1: agency_fire_id | G1: national_fire_cause | H1: fire_type_ics | I1: severity_nearest_dsr | J1: fire_was_prescribed | K1: percent_contained | L1: fire_size | M1: response_type | N1: stage_of_control_status | O1: situation_report_date | P1: status_date | Q1: latitude | R1: longitude | S1: geometry | T1: fire_year | U1: status_year | V1: record_start | W1: record_end
A2: cwfif_national_activefires.fid--5b5096eb_19f85a2ef78_-5a8c | B2: 18380651 | C2: AB | D2: LWF | E2: 2026_AB_LWF-083-2026 | F2: LWF-083-2026 | G2: N | H2: 3 | I2: -1 | J2: -1 | K2: -1 | L2: 432 | M2: FUL | N2: BH | O2: 46219.627 | P2: 46222.75 | Q2: 56.1217 | R2: -110.265 | S2: POINT (-920123.892682 894098.645139) | T2: 2026 | U2: 2026 | V2: 46223.906 | W2: 46388
A3: cwfif_national_activefires.fid--5b5096eb_19f85a2ef78_-5a8b | B3: 18380560 | C3: AB | D3: HWF | E3: 2026_AB_HWF-113-2026 | F3: HWF-113-2026 | G3: U | H3: 5 | I3: -1 | J3: -1 | K3: -1 | L3: 50 | M3: FUL | N3: UC | O3: 46218.664 | P3: 46223.614 | Q3: 59.3847 | R3: -115.094 | S3: POINT (-1092533.106795 1311654.717263) | T3: 2026 | U3: 2026 | V3: 46223.906 | W3: 46388
A4: cwfif_national_activefires.fid--5b5096eb_19f85a2ef78_-5a8a | B4: 18380652 | C4: AB | D4: LWF | E4: 2026_AB_LWF-084-2026 | F4: LWF-084-2026 | G4: N | H4: 3 | I4: -1 | J4: -1 | K4: -1 | L4: 107 | M4: FUL | N4: UC | O4: 46219.672 | P4: 46223.417 | Q4: 56.2062 | R4: -110.3258 | S4: POINT (-921519.249959 903919.00468) | T4: 2026 | U4: 2026 | V4: 46223.906 | W4: 46388
A5: cwfif_national_activefires.fid--5b5096eb_19f85a2ef78_-5a89 | B5: 18358356 | C5: AB | D5: HWF | E5: 2026_AB_HWF-114-2026 | F5: HWF-114-2026 | G5: U | H5: 5 | I5: -1 | J5: -1 | K5: -1 | L5: 51 | M5: FUL | N5: UC | O5: 46218.67 | P5: 46223.365 | Q5: 59.5259 | R5: -117.4878 | S5: POINT (-1212225.823284 1369488.529376) | T5: 2026 | U5: 2026 | V5: 46223.656 | W5: 46388
A6: cwfif_national_activefires.fid--5b5096eb_19f85a2ef78_-5a88 | B6: 18296876 | C6: AB | D6: LWF | E6: 2026_AB_LWF-082-2026 | F6: LWF-082-2026 | G6: N | H6: 3 | I6: -1 | J6: -1 | K6: -1 | L6: 76 | M6: FUL | N6: UC | O6: 46219.617 | P6: 46222.688 | Q6: 55.9728 | R6: -110.8128 | S6: POINT (-956465.758417 886439.765128) | T6: 2026 | U6: 2026 | V6: 46222.99 | W6: 46388
A7: cwfif_national_activefires.fid--5b5096eb_19f85a2ef78_-5a87 | B7: 18296875 | C7: AB | D7: LWF | E7: 2026_AB_LWF-081-2026 | F7: LWF-081-2026 | G7: N | H7: 3 | I7: -1 | J7: -1 | K7: o | L7: 25 | M7: FUL | N7: UC | O7: 46219.579 | P7: 46222.667 | Q7: 55.7187 | R7: -110.647 | S7: POINT (-953385.950998 857089.639223) | T7: 2026 | U7: 2026 | V7: 46222.99 | W7: 46388
A8: cwfif_national_activefires.fid--5b5096eb_19f85a2ef78_-5a86 | B8: 18087121 | C8: AB | D8: PWF | E8: 2026_AB_PWF-056-2026 | F8: PWF-056-2026 | G8: N | H8: 5 | I8: -1 | J8: -1 | K8: -1 | L8: 0.18 | M8: FUL | N8: UC | O8: 46219.564 | P8: 46219.885 | Q8: 57.7511 | R8: -118.18 | S8: POINT (-1316520.788436 1202987.31373) | T8: 2026 | U8: 2026 | V8: 46220.656 | W8: 46388
A9: cwfif_national_activefires.fid--5b5096eb_19f85a2ef78_-5a85 | B9: 18030172 | C9: AB | D9: MWF | E9: 2026_AB_MWF-038-2026 | F9: MWF-038-2026 | G9: N | H9: 5 | I9: -1 | J9: -1 | K9: -1 | L9: 0.16 | M9: MON | N9: UC | O9: 46218.522 | P9: 46219.479 | Q9: 56.6014 | R9: -112.1858 | S9: POINT (-1019289.422026 973942.870373) | T9: 2026 | U9: 2026 | V9: 46219.99 | W9: 46388
A10: cwfif_national_activefires.fid--5b5096eb_19f85a2ef78_-5a84 | B10: 17932365 | C10: AB | D10: HWF | E10: 2026_AB_HWF-094-2026 | F10: HWF-094-2026 | G10: N | H10: 5 | I10: -1 | J10: -1 | K10: -1 | L10: 13200 | M10: MOD | N10: UC | O10: 46198.505 | P10: 46218.353 | Q10: 59.4711 | R10: -114.7088 | S10: POINT (-1069417.577148 1314020.386942) | T10: 2026 | U10: 2026 | V10: 46218.823 | W10: 46388
A11: cwfif_national_activefires.fid--5b5096eb_19f85a2ef78_-5a83 | B11: 17562551 | C11: AB | D11: HWF | E11: 2026_AB_HWF-096-2026 | F11: HWF-096-2026 | G11: N | H11: 5 | I11: -1 | J11: -1 | K11: -1 | L11: 219.6 | M11: FUL | N11: UC | O11: 46204.394 | P11: 46213.812 | Q11: 58.8547 | R11: -117.6375 | S11: POINT (-1245306.827591 1304154.115057) | T11: 2026 | U11: 2026 | V11: 46214.115 | W11: 46388
A12: cwfif_national_activefires.fid--5b5096eb_19f85a2ef78_-5a82 | B12: 16449585 | C12: AB | D12: RWF | E12: 2026_AB_RWF-036-2026 | F12: RWF-036-2026 | G12: U | H12: 3 | I12: -1 | J12: -1 | K12: -1 | L12: 957.19 | M12: MON | N12: UC | O12: 46156.544 | P12: 46196.66 | Q12: 51.8803 | R12: -115.1532 | S12: POINT (-1350796.215932 534517.58749) | T12: 2026 | U12: 2026 | V12: 46196.948 | W12: 46388
A13: cwfif_national_activefires.fid--5b5096eb_19f85a2ef78_-5a81 | B13: 15422248 | C13: AB | D13: HWF | E13: 2026_AB_HWF-005-2026 | F13: HWF-005-2026 | G13: H | H13: 5 | I13: -1 | J13: -1 | K13: -1 | L13: 0.01 | M13: FUL | N13: UC | O13: 46137.783 | P13: 46137.783 | Q13: 58.4774 | R13: -114.521 | S13: POINT (-1092101.985211 1208166.265712) | T13: 2026 | U13: 2026 | V13: 46140.656 | W13: 46388
A14: cwfif_national_activefires.fid--5b5096eb_19f85a2ef78_-5a80 | B14: 15393793 | C14: AB | D14: HWF | E14: 2026_AB_HWF-003-2026 | F14: HWF-003-2026 | G14: H | H14: 5 | I14: -1 | J14: -1 | K14: -1 | L14: 0.01 | M14: MON | N14: UC | O14: 46113.583 | P14: 46113.59 | Q14: 58.528 | R14: -115.1647 | S14: POINT (-1125205.247982 1224610.225009) | T14: 2026 | U14: 2026 | V14: 46119.656 | W14: 46388
A15: cwfif_national_activefires.fid--5b5096eb_19f85a2ef78_-5a7f | B15: 18416839 | C15: BC | D15: V3 | E15: 2026_BC_2026-V30852 | F15: 2026-V30852 | G15: H | H15: -1 | I15: -1 | J15: 0 | K15: -1 | L15: 105.5 | M15: MON | N15: BH | O15: 46218.669 | P15: 46223.918 | Q15: 50.3046 | R15: -122.7951 | S15: POINT (-1908447.167917 568495.189572) | T15: 2026 | U15: 2026 | V15: 46224.323 | W15: 46388
A16: cwfif_national_activefires.fid--5b5096eb_19f85a2ef78_-5a7e | B16: 18410907 | C16: BC | D16: C1 | E16: 2026_BC_2026-C10968 | F16: 2026-C10968 | G16: N | H16: -1 | I16: -1 | J16: 0 | K16: -1 | L16: 0.3 | M16: FUL | N16: UC | O16: 46220.724 | P16: 46223.876 | Q16: 53.3611 | R16: -123.8289 | S16: POINT (-1827160.452382 902760.212936) | T16: 2026 | U16: 2026 | V16: 46224.281 | W16: 46388
A17: cwfif_national_activefires.fid--5b5096eb_19f85a2ef78_-5a7d | B17: 18411385 | C17: BC | D17: R9 | E17: 2026_BC_2026-R91074 | F17: 2026-R91074 | G17: N | H17: -1 | I17: -1 | J17: 0 | K17: -1 | L17: 2.5 | M17: FUL | N17: OC | O17: 46223.75 | P17: 46223.896 | Q17: 59.8227 | R17: -133.9205 | S17: POINT (-1992723.382724 1814520.579441) | T17: 2026 | U17: 2026 | V17: 46224.281 | W17: 46388
A18: cwfif_national_activefires.fid--5b5096eb_19f85a2ef78_-5a7c | B18: 18409255 | C18: BC | D18: V3 | E18: 2026_BC_2026-V31008 | F18: 2026-V31008 | G18: N | H18: -1 | I18: -1 | J18: 0 | K18: -1 | L18: 0.009 | M18: MON | N18: UC | O18: 46220.899 | P18: 46223.854 | Q18: 49.8884 | R18: -123.3344 | S18: POINT (-1962883.507958 543211.201976) | T18: 2026 | U18: 2026 | V18: 46224.24 | W18: 46388
A19: cwfif_national_activefires.fid--5b5096eb_19f85a2ef78_-5a7b | B19: 18409224 | C19: BC | D19: V1 | E19: 2026_BC_2026-V10755 | F19: 2026-V10755 | G19: H | H19: -1 | I19: -1 | J19: 0 | K19: -1 | L19: 16499 | M19: MON | N19: OC | O19: 46207.799 | P19: 46223.854 | Q19: 49.9475 | R19: -121.4584 | S19: POINT (-1838152.187521 493106.708404) | T19: 2026 | U19: 2026 | V19: 46224.24 | W19: 46388
... A250: cwfif_national_activefires.fid--5b5096eb_19f85a2ef78_-5994 | B250: 15000862 | C250: MB | D250: NO | E250: 2026_MB_MB-NO013 | F250: MB-NO013 | G250: N | H250: -1 | I250: -1 | J250: -1 | K250: -1 | L250: 500 | M250: MON | N250: OC | O250: 46174.208 | P250: 46224.559 | Q250: 58.6247 | R250: -97.0297 | S250: POINT (-114825.39927 1057067.746845) | T250: 2026 | U250: 2026 | V250: 46175.615 | W250: 46388
A251: cwfif_national_activefires.fid--5b5096eb_19f85a2ef78_-5993 | B251: 18172172 | C251: NB | E251: 2026_NB_2026310 | F251: 2026310 | G251: U | H251: -1 | I251: -1 | J251: 0 | K251: -1 | L251: 17.5 | M251: FUL | N251: UC | O251: 46219.288 | P251: 46223.365 | Q251: 45.5524 | R251: -67.0694 | S251: POINT (2142796.737969 92145.816032) | T251: 2026 | U251: 2026 | V251: 46221.615 | W251: 46388
A252: cwfif_national_activefires.fid--5b5096eb_19f85a2ef78_-5992 | B252: 18242715 | C252: NL | E252: 2026_NL_606 | F252: 606 | G252: N | H252: -1 | I252: -1 | J252: 0 | K252: -1 | L252: 12100 | M252: MON | N252: UC | O252: 46199.104 | P252: 46224.698 | Q252: 53.4957 | R252: -65.751 | S252: POINT (1845346.709977 928132.285584) | T252: 2026 | U252: 2026 | V252: 46222.406 | W252: 46388
A253: cwfif_national_activefires.fid--5b5096eb_19f85a2ef78_-5991 | B253: 18155292 | C253: NL | E253: 2026_NL_617 | F253: 617 | G253: N | H253: -1 | I253: -1 | J253: 0 | K253: -1 | L253: 850 | M253: MON | N253: UC | O253: 46201.104 | P253: 46224.698 | Q253: 54.3182 | R253: -66.1047 | S253: POINT (1785073.489603 998864.226154) | T253: 2026 | U253: 2026 | V253: 46221.406 | W253: 46388
A254: cwfif_national_activefires.fid--5b5096eb_19f85a2ef78_-5990 | B254: 18155310 | C254: NL | E254: 2026_NL_636 | F254: 636 | G254: N | H254: -1 | I254: -1 | J254: 0 | K254: -1 | L254: 3146.6 | M254: FUL | N254: UC | O254: 46210.104 | P254: 46224.698 | Q254: 52.349 | R254: -65.799 | S254: POINT (1898328.347917 813869.883558) | T254: 2026 | U254: 2026 | V254: 46221.406 | W254: 46388
A255: cwfif_national_activefires.fid--5b5096eb_19f85a2ef78_-598f | B255: 18155280 | C255: NL | E255: 2026_NL_605 | F255: 605 | G255: N | H255: -1 | I255: -1 | J255: 0 | K255: -1 | L255: 6855.4 | M255: MON | N255: UC | O255: 46198.104 | P255: 46224.698 | Q255: 52.4064 | R255: -66.1111 | S255: POINT (1876692.726094 810273.86715) | T255: 2026 | U255: 2026 | V255: 46221.406 | W255: 46388
A256: cwfif_national_activefires.fid--5b5096eb_19f85a2ef78_-598e | B256: 18155313 | C256: NL | E256: 2026_NL_639 | F256: 639 | G256: N | H256: -1 | I256: -1 | J256: 0 | K256: -1 | L256: 300 | M256: FUL | N256: UC | O256: 46211.104 | P256: 46224.698 | Q256: 52.9889 | R256: -67.3467 | S256: POINT (1774716.79383 832590.173868) | T256: 2026 | U256: 2026 | V256: 46221.406 | W256: 46388
A257: cwfif_national_activefires.fid--5b5096eb_19f85a2ef78_-598d | B257: 18286390 | C257: NS | D257: 9 | E257: 2026_NS_09-013-2026 | F257: 09-013-2026 | G257: U | H257: -1 | I257: -1 | J257: 0 | K257: 100 | L257: 1447 | M257: FUL | N257: BH | O257: 46218.792 | P257: 46219.542 | Q257: 44.9018 | R257: -62.7207 | S257: POINT (2485167.868106 184970.695114) | T257: 2026 | U257: 2026 | V257: 46222.865 | W257: 46388
A258: cwfif_national_activefires.fid--5b5096eb_19f85a2ef78_-598c | B258: 18108570 | C258: NS | D258: 6 | E258: 2026_NS_06-013-2026 | F258: 06-013-2026 | G258: U | H258: -1 | I258: -1 | J258: 0 | K258: 100 | L258: 5 | M258: FUL | N258: UC | O258: 46218.792 | P258: 46219.542 | Q258: 44.6856 | R258: -65.45 | S258: POINT (2302131.964595 60598.539594) | T258: 2026 | U258: 2026 | V258: 46220.906 | W258: 46388
A259: cwfif_national_activefires.fid--5b5096eb_19f85a2ef78_-598b | B259: 18393157 | C259: NT | D259: FS | E259: 2026_NT_FS045-26 | F259: FS045-26 | G259: N | H259: -1 | I259: -1 | J259: -1 | K259: -1 | L259: 16093 | M259: MON | N259: OC | O259: 46216.983 | P259: 46224.698 | Q259: 62.437 | R259: -121.7494 | S259: POINT (-1300816.548412 1745567.122881) | T259: 2026 | U259: 2026 | V259: 46224.073 | W259: 46388
A260: cwfif_national_activefires.fid--5b5096eb_19f85a2ef78_-598a | B260: 18385970 | C260: NT | D260: SS | E260: 2026_NT_SS045-26 | F260: SS045-26 | G260: N | H260: -1 | I260: -1 | J260: -1 | K260: -1 | L260: 10 | M260: MON | N260: OC | O260: 46223.903 | P260: 46224.698 | Q260: 60.3537 | R260: -110.223 | S260: POINT (-808727.253603 1339831.233852) | T260: 2026 | U260: 2026 | V260: 46223.99 | W260: 46388
A261: cwfif_national_activefires.fid--5b5096eb_19f85a2ef78_-5989 | B261: 18385968 | C261: NT | D261: SS | E261: 2026_NT_SS043-26 | F261: SS043-26 | G261: N | H261: -1 | I261: -1 | J261: -1 | K261: -1 | L261: 23 | M261: MON | N261: OC | O261: 46220.607 | P261: 46224.698 | Q261: 61.1499 | R261: -103.3973 | S261: POINT (-437750.717455 1357685.61514) | T261: 2026 | U261: 2026 | V261: 46223.99 | W261: 46388
A262: cwfif_national_activefires.fid--5b5096eb_19f85a2ef78_-5988 | B262: 18385967 | C262: NT | D262: SS | E262: 2026_NT_SS042-26 | F262: SS042-26 | G262: N | H262: -1 | I262: -1 | J262: -1 | K262: -1 | L262: 0.1 | M262: FUL | N262: OC | O262: 46223.781 | P262: 46224.698 | Q262: 61.0212 | R262: -109.8518 | S262: POINT (-772662.175163 1405441.986235) | T262: 2026 | U262: 2026 | V262: 46223.99 | W262: 46388
A263: cwfif_national_activefires.fid--5b5096eb_19f85a2ef78_-5987 | B263: 18385969 | C263: NT | D263: SS | E263: 2026_NT_SS044-26 | F263: SS044-26 | G263: N | H263: -1 | I263: -1 | J263: -1 | K263: -1 | L263: 15 | M263: MON | N263: OC | O263: 46219.956 | P263: 46224.698 | Q263: 61.5915 | R263: -106.1839 | S263: POINT (-573347.110586 1427054.519582) | T263: 2026 | U263: 2026 | V263: 46223.99 | W263: 46388
A264: cwfif_national_activefires.fid--5b5096eb_19f85a2ef78_-5986 | B264: 18382451 | C264: NT | D264: VQ | E264: 2026_NT_VQ050-26 | F264: VQ050-26 | G264: N | H264: -1 | I264: -1 | J264: -1 | K264: -1 | L264: 0.1 | M264: MON | N264: OC | O264: 46201.59 | P264: 46224.698 | Q264: 65.7345 | R264: -124.5132 | S264: POINT (-1266423.17107 2123550.924499) | T264: 2026 | U264: 2026 | V264: 46223.948 | W264: 46388
A265: cwfif_national_activefires.fid--5b5096eb_19f85a2ef78_-5985 | B265: 18377323 | C265: NT | D265: VQ | E265: 2026_NT_VQ076-26 | F265: VQ076-26 | G265: N | H265: -1 | I265: -1 | J265: -1 | K265: -1 | L265: 1 | M265: MON | N265: OC | O265: 46223.785 | P265: 46224.698 | Q265: 65.3168 | R265: -125.6057 | S265: POINT (-1330602.490458 2105643.652259) | T265: 2026 | U265: 2026 | V265: 46223.865 | W265: 46388
A266: cwfif_national_activefires.fid--5b5096eb_19f85a2ef78_-5984 | B266: 18371824 | C266: NT | D266: SS | E266: 2026_NT_SS050-26 | F266: SS050-26 | G266: N | H266: -1 | I266: -1 | J266: -1 | K266: -1 | L266: 0.1 | M266: MON | N266: OC | O266: 46201.59 | P266: 46224.698 | Q266: 61.032 | R266: -109.8518 | S266: POINT (-772392.084078 1406582.146897) | T266: 2026 | U266: 2026 | V266: 46223.823 | W266: 46388
A267: cwfif_national_activefires.fid--5b5096eb_19f85a2ef78_-5983 | B267: 18357773 | C267: NT | D267: ZF | E267: 2026_NT_ZF028-26 | F267: ZF028-26 | G267: N | H267: -1 | I267: -1 | J267: -1 | K267: -1 | L267: 15702 | M267: FUL | N267: OC | O267: 46207.017 | P267: 46224.698 | Q267: 63.1468 | R267: -116.424 | S267: POINT (-1027664.761932 1719383.456474) | T267: 2026 | U267: 2026 | V267: 46223.656 | W267: 46388
A268: cwfif_national_activefires.fid--5b5096eb_19f85a2ef78_-5982 | B268: 18287940 | C268: NT | D268: ZF | E268: 2026_NT_ZF058-26 | F268: ZF058-26 | G268: N | H268: -1 | I268: -1 | J268: -1 | K268: -1 | L268: 12950 | M268: MON | N268: OC | O268: 46220.629 | P268: 46224.698 | Q268: 64.2212 | R268: -117.8477 | S268: POINT (-1052274.803294 1851822.172816) | T268: 2026 | U268: 2026 | V268: 46222.865 | W268: 46388
A269: cwfif_national_activefires.fid--5b5096eb_19f85a2ef78_-5981 | B269: 18282135 | C269: NT | D269: EV | E269: 2026_NT_EV010-26 | F269: EV010-26 | G269: N | H269: -1 | I269: -1 | J269: -1 | K269: -1 | L269: 35 | M269: MON | N269: OC | O269: 46216.729 | P269: 46224.698 | Q269: 65.8667 | R269: -132.1953 | S269: POINT (-1554204.945199 2306489.32487) | T269: 2026 | U269: 2026 | V269: 46222.823 | W269: 46388
A270: cwfif_national_activefires.fid--5b5096eb_19f85a2ef78_-5980 | B270: 18216114 | C270: NT | D270: VQ | E270: 2026_NT_VQ075-26 | F270: VQ075-26 | G270: N | H270: -1 | I270: -1 | J270: -1 | K270: -1 | L270: 10 | M270: MON | N270: OC | O270: 46222.003 | P270: 46224.698 | Q270: 64.8031 | R270: -120.0545 | S270: POINT (-1124709.23426 1948085.984658) | T270: 2026 | U270: 2026 | V270: 46222.073 | W270: 46388
...

Sheet pivot table + ANOVA
A3: national_fire_cause | B3: Sum of fire_size
A4: H | B4: 110064.07 | G4: ANOVA - Single Factor
A5: N | B5: 2537919.2 | G5: Alpha | H5: 0.05
A6: U | B6: 134676.79
A7: (empty) | G7: Groups | H7: Count | I7: Sum | J7: Mean | K7: Variance
A8: Total Result | B8: 2782660.1 | G8: Column 1 | H8: =COUNT('pivot table + ANOVA'!$B$4:$B$6) -> 3 | I8: =SUM('pivot table + ANOVA'!$B$4:$B$6) -> 2782660.1 | J8: =AVERAGE('pivot table + ANOVA'!$B$4:$B$6) -> 927553.35 | K8: =VAR('pivot table + ANOVA'!$B$4:$B$6) -> 1.9451101e+12
G10: Source of Variation | H10: SS | I10: df | J10: MS | K10: F | L10: P-value | M10: F critical
G11: Between Groups | H11: =SUMPRODUCT('pivot table + ANOVA'!$I$8,'pivot table + ANOVA'!$J$8)-SUM('pivot table + ANOVA'!$I$8)^2/SUM('pivot table + ANOVA'!$H$8) -> 0 | I11: =COUNT('pivot table + ANOVA'!$I$8)-1 -> 0 | J11: ='pivot table + ANOVA'!$H$11 / 'pivot table + ANOVA'!$I$11 -> #DIV/0! | K11: ='pivot table + ANOVA'!$J$11 / 'pivot table + ANOVA'!$J$12 -> #DIV/0! | L11: =FDIST('pivot table + ANOVA'!$K$11, 'pivot table + ANOVA'!$I$11, 'pivot table + ANOVA'!$I$12) -> #DIV/0! | M11: =FINV('pivot table + ANOVA'!$H$5, 'pivot table + ANOVA'!$I$11, 'pivot table + ANOVA'!$I$12) -> #VALUE!
G12: Within Groups | H12: =SUM(DEVSQ('pivot table + ANOVA'!$B$4:$B$6)) -> 3.8902202e+12 | I12: =SUM('pivot table + ANOVA'!$H$8)-COUNT('pivot table + ANOVA'!$H$8) -> 2 | J12: ='pivot table + ANOVA'!$H$12 / 'pivot table + ANOVA'!$I$12 -> 1.9451101e+12
G13: Total | H13: =DEVSQ('pivot table + ANOVA'!$B$4:$B$6) -> 3.8902202e+12 | I13: =SUM('pivot table + ANOVA'!$H$8) - 1 -> 2

Sheet descriptive stats
A1: fire_size | F1: Notes
A2: 432 | C2: Descriptive Stats | F2: (units are in hectares)
A3: 50 | C3: Mean | D3: =AVERAGE(A2:A890) -> 3130.1013 | F3: (-1 denotes the fire size for some fires is not reported)
A4: 107 | C4: Median | D4: =MEDIAN(A2:A890) -> 94.7
A5: 51 | C5: Standard Deviation | D5: =STDEV(A2:A890) -> 14341.414
A6: 76 | C6: Skewness | D6: =SKEW(A2:A890) -> 14.445065
A7: 25 | C7: Range | D7: =D9-D8 -> 318813.7
A8: 0.18 | C8: Minimum | D8: =MIN(A2:A890) -> -1
A9: 0.16 | C9: Maximum | D9: =MAX(A2:A890) -> 318812.7
A10: 13200 | C10: Sum | D10: =SUM(A2:A890) -> 2782660.1
A11: 219.6
A12: 957.19
A13: 0.01
A14: 0.01
A15: 105.5
A16: 0.3
A17: 2.5
A18: 0.009
A19: 16499
A20: 4261
A21: 0.08
A22: 0.01
... A890: 1

Sheet pie chart
A1: national_fire_cause
A2: N | C2: Fire Cause Class | D2: Total | E2: Percentage
A3: U | C3: N | D3: =COUNTIF(A2:A890, C3) -> 818 | E3: =(D3/D7)*100 -> 92.117117
A4: N | C4: H | D4: =COUNTIF(A3:A891, C4) -> 52 | E4: =(D4/D$7)*100 -> 5.8558559
A5: U | C5: U | D5: =COUNTIF(A4:A892, C5) -> 18 | E5: =(D5/D$7)*100 -> 2.027027
A6: N
A7: N | C7: Grand Total | D7: =SUM(D3:D5) -> 888
A8: N
A9: N
A10: N
A11: N
A12: U
A13: H
A14: H
A15: H
A16: N
A17: N
A18: N
A19: H
... A890: U
